Workbook

Sheet Dashboard
B1: Batch Analysis Dashboard
B5: Description | C5: Steps | D5: Effort Hours (hrs) | E5: Initial Analysis | L5: Virus Inactivation
B6: Virus Inactivation | C6: ='Virus Inactivation'!O4 -> 11 | D6: ='Virus Inactivation'!P4 -> 632 | E6: 2 templates
B7: Virus Filtration | C7: ='Virus Filtration'!O4 -> 21 | D7: ='Virus Filtration'!P4 -> 1092
B8: Chromatography 1 | C8: ='Chromatography 1'!O4 -> 29 | D8: ='Chromatography 1'!P4 -> 1520 | E8: 3 templates
B9: Chromatography 2 | C9: ='Chromatography 2'!O4 -> 29 | D9: ='Chromatography 2'!P4 -> 1784
B10: Conjugation 1 | C10: ='Conjugation 1'!O4 -> 23 | D10: ='Conjugation 1'!P4 -> 1256 | E10: 2 templates
B11: Conjugation 2 | C11: ='Conjugation 2'!O4 -> 8 | D11: ='Conjugation 2'!P4 -> 296
B12: Bulk Formulation | C12: 17 | D12: 1088 | E12: 1 template
C13: =SUM(Table3[Steps]) -> 138 | D13: =SUM(Table3[Effort Hours (hrs)]) -> 7668
L25: Virus Filtration
L51: Chromatography 1
L77: Chromatography 2
L103: Conjugation 1
L129: Conjugation 2
L155: Bulk Formulation

Sheet Virus Inactivation
A1: Virus Iactivation Batch Record Analysis
A2: Batch ID: PN - 8012441 | N2: Analysis Type | O2: Total Steps | P2: Effort Hours (hrs)
N3: Detailed Analysis | O3: =Detailed_Analysis_2[[#Totals],[Step Num]] -> 80 | P3: =Detailed_Analysis_2[[#Totals],[Effort Hours (hrs)]] -> 3080
N4: Streamlined Analysis | O4: =Streamlined_Analysis_2[[#Totals],[Step Num]] -> 11 | P4: =Streamlined_Analysis_2[[#Totals],[Effort Hours (hrs)]] -> 632
A6: Step Num | B6: Title | C6: Brief Description | D6: Complexity | E6: Effort Hours (hrs) | G6: Step Num | H6: Title | I6: Brief Description | J6: Complexity | K6: Effort Hours (hrs)
A7: 7.1 | B7: Record Room Number | C7: Record the room where the VI process will occur. Simple room number entry with signature. | D7: LOW | E7: =IF(D7="LOW", 16, IF(D7="MEDIUM", 40, IF(D7="HIGH", 100, ""))) -> 16 | G7: 7.1 | H7: Measure pH, Conductivity, Temperature | I7: Measure pH, conductivity (mS/cm), and temperature (°C) of Affinity product per SOP-0080297 and SOP-0107117. Record all three values. | J7: MEDIUM | K7: =IF(J7="LOW", 16, IF(J7="MEDIUM", 40, IF(J7="HIGH", 100, ""))) -> 40
A8: 7.2 | B8: Verify Affinity Product Warm-Up Time | C8: If Affinity Product was warmed from cold storage, ensure time removed from 2-8°C storage matches Attachment 3 hold time. Conditional check. | D8: LOW | E8: =IF(D8="LOW", 16, IF(D8="MEDIUM", 40, IF(D8="HIGH", 100, ""))) -> 16 | G8: 7.14 | H8: Starting Product Temperature Check / Decision Tree | I8: Conditional decision tree based on temperature: 18-25°C → proceed to Step 10.9; <18°C → start warming (Section 9); >25°C → contact supervisor. Cross-reference to multiple sections. | J8: MEDIUM | K8: =IF(J8="LOW", 16, IF(J8="MEDIUM", 40, IF(J8="HIGH", 100, ""))) -> 40
A9: 7.3 | B9: Verify pH Meter Standardization (pH 2.0-7.0) | C9: Confirm pH meter standardized between pH 2.0 and pH 7.0 per SOP-0080297. Confirm thermometer calibrated per SOP-0107117. Record Meter ID. | D9: MEDIUM | E9: =IF(D9="LOW", 16, IF(D9="MEDIUM", 40, IF(D9="HIGH", 100, ""))) -> 40 | G9: 8.4 | H9: VI Treatment Vessel Setup - Comprehensive | I9: Complex vessel setup form: Bag info (Part No., Batch No., Exp. Date, SAP consumption), mixer drive/top base/magnetic clamp attachments, OR Tank info (Tank ID, CIP Batch, CIP Exp, Pressure Test, SIP Batch). Filter info for vent filter + up to 3 product filters with autoclave tracking. Tare weight recording with scale ID. | J9: HIGH | K9: =IF(J9="LOW", 16, IF(J9="MEDIUM", 40, IF(J9="HIGH", 100, ""))) -> 100
A10: 7.4 | B10: Verify Thermometer Calibration | C10: Confirm thermometer is within calibration interval per SOP-0107117. Record Thermometer ID. | D10: LOW | E10: =IF(D10="LOW", 16, IF(D10="MEDIUM", 40, IF(D10="HIGH", 100, ""))) -> 16 | G10: 10.9 | H10: Acid Treatment - Iterative pH Titration Table | I10: Complex iterative acid addition table: Record initial pH, conductivity, temperature (18-25°C), start time. For each addition cycle: gross weight before, end time, gross weight after, net weight of buffer added (calculation), total net weight, time of pH sampling, adjusted pH, sample temperature. Up to 12 addition rows. Target pH 3.5 (NOR 3.4-3.6). Record final pH confirmed time, final pH, final conductivity, temperature, SAP consumption, Start Time for Incubation. | J10: HIGH | K10: =IF(J10="LOW", 16, IF(J10="MEDIUM", 40, IF(J10="HIGH", 100, ""))) -> 100
A11: 7.5 | B11: Record Tare and Net Weight of Affinity Product | C11: Record tare weight and net weight of AZD0543 Affinity Product vessel. Record SoloVPE concentration (8012440-30), DLIMS Project/Sample numbers. | D11: MEDIUM | E11: =IF(D11="LOW", 16, IF(D11="MEDIUM", 40, IF(D11="HIGH", 100, ""))) -> 40 | G11: 12.1 | H11: Ensure Agitation (Extension) | I11: Ensure agitation is on for the extension acid addition. | J11: LOW | K11: =IF(J11="LOW", 16, IF(J11="MEDIUM", 40, IF(J11="HIGH", 100, ""))) -> 16
A12: 7.6 | B12: Mix Product (≥15 minutes) | C12: Mix product for at least 15 minutes per SOP-0080423 (LevTech) or SOP-0107102 (MagMix) or SOP-0107095 (tank). Record Mixer ID, agitation RPM, start/end times, calculate duration. | D12: MEDIUM | E12: =IF(D12="LOW", 16, IF(D12="MEDIUM", 40, IF(D12="HIGH", 100, ""))) -> 40 | G12: 14.11 | H12: Neutralization Treatment - Iterative pH Titration Table | I12: Complex iterative base addition table: Record scale/balance ID, calibration date. For each addition: gross weight before, end time, gross weight after, net weight buffer added (calculation), total net weight, pH sampling time, adjusted pH. Up to 5 addition rows. SAP consumption. Record final pH (7.2-7.6), final conductivity, temperature (15-27°C). | J12: HIGH | K12: =IF(J12="LOW", 16, IF(J12="MEDIUM", 40, IF(J12="HIGH", 100, ""))) -> 100
A13: 7.7 | B13: Collect Pre-Treatment Sample (8012441-10) | C13: Remove sample volume per Attachment 1 and SOP-0107097. Record sampling date/time. Non-routine samples per Attachment 2 if applicable. | D13: LOW | E13: =IF(D13="LOW", 16, IF(D13="MEDIUM", 40, IF(D13="HIGH", 100, ""))) -> 16 | G13: 14.15 | H13: Calculate Net Weight of Neutralized VI Product | I13: Calculate: Net Weight of Affinity (Step 7.12 or 8.10) + Total Net Weight of Acid (Step 10.9 or 12.4) + Total Net Weight of Base (Step 14.11) = Net Weight/Volume of Neutralized VI Product (kg=L). Multi-step cross-reference calculation. | J13: LOW | K13: =IF(J13="LOW", 16, IF(J13="MEDIUM", 40, IF(J13="HIGH", 100, ""))) -> 16
A14: 7.8 | B14: Aliquot Sample per Attachment 1 | C14: Aliquot sample (8012441-10) per Attachment 1: Sampling Record. Aliquot non-routine samples per Attachment 2 if applicable. | D14: LOW | E14: =IF(D14="LOW", 16, IF(D14="MEDIUM", 40, IF(D14="HIGH", 100, ""))) -> 16 | G14: 15.5 | H14: Measure Final pH, Conductivity, Temperature | I14: Measure pH (7.2-7.6), conductivity (mS/cm), temperature (°C) of neutralized VI product. Contact Supervisor if pH outside 7.2-7.6. | J14: MEDIUM | K14: =IF(J14="LOW", 16, IF(J14="MEDIUM", 40, IF(J14="HIGH", 100, ""))) -> 40
A15: 7.9 | B15: Submit Sample to DLIMS Storage | C15: Submit sample to storage location indicated in DLIMS per SOP-0080295. Ensure sampling tube label information matches DLIMS. | D15: LOW | E15: =IF(D15="LOW", 16, IF(D15="MEDIUM", 40, IF(D15="HIGH", 100, ""))) -> 16 | G15: 15.8 | H15: Store Product and Document Hold Times | I15: Store product, document storage info. Record hold times in Attachment 3. Map: Start time of addition → Affinity Product Storage End. | J15: MEDIUM | K15: =IF(J15="LOW", 16, IF(J15="MEDIUM", 40, IF(J15="HIGH", 100, ""))) -> 40
A16: 7.1 | B16: Measure pH, Conductivity, Temperature | C16: Measure pH, conductivity (mS/cm), and temperature (°C) of Affinity product per SOP-0080297 and SOP-0107117. Record all three values. | D16: MEDIUM | E16: =IF(D16="LOW", 16, IF(D16="MEDIUM", 40, IF(D16="HIGH", 100, ""))) -> 40 | G16: ATT-3 | H16: Attachment 3: Hold Times | I16: Affinity Product storage tracking: up to 3 holds with Location, Temperature (RT or 2-8°C), Storage Start/End times, calculated hold durations for RT and 2-8°C separately. Total RT Hold Time (alert if >72 hrs), Total 2-8°C Hold Time, Total Combined Hold Time (alert if >168 hrs). Requires calculations and conditional supervisor contact. | J16: HIGH | K16: =IF(J16="LOW", 16, IF(J16="MEDIUM", 40, IF(J16="HIGH", 100, ""))) -> 100
A17: 7.11 | B17: Obtain Gross Weight After Sampling | C17: Obtain gross weight of Affinity product vessel after sampling. Record Scale/Balance ID and Calibration Due Date. | D17: LOW | E17: =IF(D17="LOW", 16, IF(D17="MEDIUM", 40, IF(D17="HIGH", 100, ""))) -> 16 | G17: ATT-5 | H17: Attachment 5: Transfer Tubing/Hosing Information | I17: Material tracking for up to 3 tubing/hoses: Part No., Batch No., Exp. Date, Autoclave Cycle No./Exp. Date (if applicable), Hose Serial No., Cleaning Batch ID/Exp. Date. Dual signature. | J17: MEDIUM | K17: =IF(J17="LOW", 16, IF(J17="MEDIUM", 40, IF(J17="HIGH", 100, ""))) -> 40
A18: 7.12 | B18: Calculate Net Weight After Sampling | C18: Calculate net weight: Gross Weight (Step 7.11) − Tare Weight (Step 7.5) = Affinity Weight/Volume after sampling (kg=L). | D18: MEDIUM | E18: =IF(D18="LOW", 16, IF(D18="MEDIUM", 40, IF(D18="HIGH", 100, ""))) -> 40 | G18: =COUNTA(Streamlined_Analysis_2[Step Num]) -> 11 | K18: =SUM(Streamlined_Analysis_2[Effort Hours (hrs)]) -> 632
A19: 7.13 | B19: SAP Consumption Recording | C19: Record SAP consumption for materials used in Section 7. | D19: LOW | E19: =IF(D19="LOW", 16, IF(D19="MEDIUM", 40, IF(D19="HIGH", 100, ""))) -> 16
A20: 7.14 | B20: Starting Product Temperature Check / Decision Tree | C20: Conditional decision tree based on temperature: 18-25°C → proceed to Step 10.9; <18°C → start warming (Section 9); >25°C → contact supervisor. Cross-reference to multiple sections. | D20: HIGH | E20: =IF(D20="LOW", 16, IF(D20="MEDIUM", 40, IF(D20="HIGH", 100, ""))) -> 100
A21: 8.1 | B21: N/A Check - Same Vessel for VI | C21: If Affinity product vessel will be used as VI Treatment Vessel, N/A all of Section 8, go to Section 9 or 10. | D21: LOW | E21: =IF(D21="LOW", 16, IF(D21="MEDIUM", 40, IF(D21="HIGH", 100, ""))) -> 16
A22: 8.2 | B22: Obtain and Label VI Treatment Vessel | C22: Obtain product vessel, label with AZD0543, VI Treatment Vessel, batch number per SOP-0107056. | D22: LOW | E22: =IF(D22="LOW", 16, IF(D22="MEDIUM", 40, IF(D22="HIGH", 100, ""))) -> 16
A23: 8.3 | B23: Record Bill of Materials Info | C23: Record solution batch numbers from Section 5 Document Process Flow Sheet. Starting Material (PN 8012440), Acid (PN A-005168), Base (PN A0101-D). | D23: MEDIUM | E23: =IF(D23="LOW", 16, IF(D23="MEDIUM", 40, IF(D23="HIGH", 100, ""))) -> 40
A24: 8.4 | B24: VI Treatment Vessel Setup - Comprehensive | C24: Complex vessel setup form: Bag info (Part No., Batch No., Exp. Date, SAP consumption), mixer drive/top base/magnetic clamp attachments, OR Tank info (Tank ID, CIP Batch, CIP Exp, Pressure Test, SIP Batch). Filter info for vent filter + up to 3 product filters with autoclave tracking. Tare weight recording with scale ID. | D24: HIGH | E24: =IF(D24="LOW", 16, IF(D24="MEDIUM", 40, IF(D24="HIGH", 100, ""))) -> 100
A25: 8.5 | B25: Obtain Transfer Tubing/Hosing | C25: Obtain transfer tubing or clean flex hose. Record info in Attachment 5: Transfer Tubing/Hosing Information. | D25: LOW | E25: =IF(D25="LOW", 16, IF(D25="MEDIUM", 40, IF(D25="HIGH", 100, ""))) -> 16
A26: 8.6 | B26: Connect Transfer Tubing | C26: Connect transfer tubing/hose from outlet of Affinity Product Vessel to inlet of VI Treatment Vessel. Confirm dip tube orientation for tanks. | D26: LOW | E26: =IF(D26="LOW", 16, IF(D26="MEDIUM", 40, IF(D26="HIGH", 100, ""))) -> 16
A27: 8.7 | B27: Transfer Affinity Product | C27: Transfer all Affinity product to VI Treatment Vessel. Disconnect transfer tubing after completion. | D27: MEDIUM | E27: =IF(D27="LOW", 16, IF(D27="MEDIUM", 40, IF(D27="HIGH", 100, ""))) -> 40
A28: 8.8 | B28: Mix Product in Treatment Vessel (≥15 min) | C28: Mix product ≥15 minutes per SOP-0107102 (MagMix) or SOP-0107095 (tank). Record Mixer ID, agitation RPM, start/end times, duration. | D28: MEDIUM | E28: =IF(D28="LOW", 16, IF(D28="MEDIUM", 40, IF(D28="HIGH", 100, ""))) -> 40
A29: 8.9 | B29: Measure Temperature After Transfer | C29: Aliquot 10 mL sample into 50 mL conical, measure temperature. Record Scale/Balance ID, Calibration Due Date. Obtain gross and net weight after sampling. | D29: MEDIUM | E29: =IF(D29="LOW", 16, IF(D29="MEDIUM", 40, IF(D29="HIGH", 100, ""))) -> 40
A30: 8.1 | B30: Calculate Net Weight in Treatment Vessel | C30: Calculate net weight: Gross Weight − Tare Weight (Step 8.4) = Net weight in VI Treatment Vessel (kg=L). | D30: MEDIUM | E30: =IF(D30="LOW", 16, IF(D30="MEDIUM", 40, IF(D30="HIGH", 100, ""))) -> 40
... A79: 16.3 | B79: Review and Submit Batch Record | C79: Review Batch Production Record for completeness and submit for Production and QA review. | D79: LOW | E79: =IF(D79="LOW", 16, IF(D79="MEDIUM", 40, IF(D79="HIGH", 100, ""))) -> 16
A80: ATT-1 | B80: Attachment 1: Sampling Record | C80: Detailed sampling record table for VI (8012441) with DLIMS Project #, pre-load signature. 11 sample types across 2 designations (-10 Affinity Product and -30 VI Product). Samples: BIOBURDEN_IP, ENDOTOXIN_IP_GPF1, SOLO_A280 (STAT), CIEF_NATIV, CHO_SYBR, EL_CHO_GEN, SEC_PUR, CGE_N_RED, ABT Retain (5×14mL), PPS Small Retain (3×14mL). Record volume, location, tube type, intermediate storage temp, DLIMS storage temp, sample numbers. | D80: MEDIUM | E80: =IF(D80="LOW", 16, IF(D80="MEDIUM", 40, IF(D80="HIGH", 100, ""))) -> 40
A81: ATT-2 | B81: Attachment 2: Non-Routine Sampling Record | C81: Form for documenting non-routine samples: Process Section No., Contents, DLIMS Form/Project/Sample Number, Container Type, Quantity, Tests, Designation, Receiving Group, Storage Temp. Re-adjust weight if non-routine samples taken. Up to 5 entries. | D81: LOW | E81: =IF(D81="LOW", 16, IF(D81="MEDIUM", 40, IF(D81="HIGH", 100, ""))) -> 16
A82: ATT-3 | B82: Attachment 3: Hold Times | C82: Affinity Product storage tracking: up to 3 holds with Location, Temperature (RT or 2-8°C), Storage Start/End times, calculated hold durations for RT and 2-8°C separately. Total RT Hold Time (alert if >72 hrs), Total 2-8°C Hold Time, Total Combined Hold Time (alert if >168 hrs). Requires calculations and conditional supervisor contact. | D82: HIGH | E82: =IF(D82="LOW", 16, IF(D82="MEDIUM", 40, IF(D82="HIGH", 100, ""))) -> 100
A83: ATT-4 | B83: Attachment 4: Yield Calculations | C83: Multi-step yield calculations: Load Mass Pre-Sampling (Volume × Concentration), Load Mass Post-Sampling, Final Product Mass Pre-Sampling (Step 14.15 × concentration from 8012441-30), Final Product Mass Post-Sampling (Step 15.7 × concentration). Step Yield = (c)÷(b)×100%. MPR Yield = (d)÷(a)×100%. Cross-references to multiple steps. | D83: HIGH | E83: =IF(D83="LOW", 16, IF(D83="MEDIUM", 40, IF(D83="HIGH", 100, ""))) -> 100
A84: ATT-5 | B84: Attachment 5: Transfer Tubing/Hosing Information | C84: Material tracking for up to 3 tubing/hoses: Part No., Batch No., Exp. Date, Autoclave Cycle No./Exp. Date (if applicable), Hose Serial No., Cleaning Batch ID/Exp. Date. Dual signature. | D84: MEDIUM | E84: =IF(D84="LOW", 16, IF(D84="MEDIUM", 40, IF(D84="HIGH", 100, ""))) -> 40
A85: ATT-6 | B85: Attachment 6: Product Recirculation Worksheet | C85: Recirculation tracking for Sections 7, 8, 9, and 15: Product Name, Tubing Part/Batch/Exp/Autoclave info, Mixing Start/End Time, Mixing Duration (≥40 minutes). Four column entries for different process sections. | D85: MEDIUM | E85: =IF(D85="LOW", 16, IF(D85="MEDIUM", 40, IF(D85="HIGH", 100, ""))) -> 40
A86: ATT-7 | B86: Attachment 7: Comments Section | C86: 4-page free-text form for documenting deviations, supervisor decisions, out-of-specification events, process notes, and any additional information. Step No., Comments (initial and date each entry), Initials/Date columns. Approximately 44 blank rows across pages. | D86: LOW | E86: =IF(D86="LOW", 16, IF(D86="MEDIUM", 40, IF(D86="HIGH", 100, ""))) -> 16
A87: =COUNTA(Detailed_Analysis_2[Step Num]) -> 80 | E87: =SUM(Detailed_Analysis_2[Effort Hours (hrs)]) -> 3080

Sheet Virus Filtration
A1: Virus Filtration Batch Record Analysis
A2: Batch ID: PN - 8012475 | N2: Analysis Type | O2: Total Steps | P2: Effort Hours (hrs)
N3: Detailed Analysis | O3: =Detailed_Analysis_3[[#Totals],[Step Num]] -> 247 | P3: =Detailed_Analysis_3[[#Totals],[Effort Hours (hrs)]] -> 11932
N4: Streamlined Analysis | O4: =Streamlined_Analysis_3[[#Totals],[Step Num]] -> 21 | P4: =Streamlined_Analysis_3[[#Totals],[Effort Hours (hrs)]] -> 1092
A6: Step Num | B6: Title | C6: Brief Description | D6: Complexity | E6: Effort Hours (hrs) | G6: Step Num | H6: Title | I6: Brief Description | J6: Complexity | K6: Effort Hours (hrs)
A7: 7.1 | B7: Record Room Number | C7: Record the room number where this process will occur. | Room Number | D7: LOW | E7: =IF(D7="LOW", 16, IF(D7="MEDIUM", 40, IF(D7="HIGH", 100, ""))) -> 16 | G7: 7.2 | H7: Record CIPDS/Skid Information | I7: Obtain and record the following information from the AZD0543 CIPDS (FORM-0071789) and Skid Logbook. | CIPDS part number | CIPDS lot number | Skid ID | Cassette installation date | No. of cassettes used | Cassette part number | Cassette batch number | Cassette expiration date | Additional cassette batch number, if applicable | Additional cassette expiration date, if applicable | Hold-up volume of the UF/DF Skid | Total surface area of cassettes | Support Plate part number | Support Plate batch number | Support Plate expiration date | Logbook Number | CIPDS SAP Consumption Performed by/Date | J7: HIGH | K7: =IF(J7="LOW", 16, IF(J7="MEDIUM", 40, IF(J7="HIGH", 100, ""))) -> 100
A8: 7.2 | B8: Record CIPDS/Skid Information | C8: Obtain and record the following information from the AZD0543 CIPDS (FORM-0071789) and Skid Logbook. | CIPDS part number | CIPDS lot number | Skid ID | Cassette installation date | No. of cassettes used | Cassette part number | Cassette batch number | Cassette expiration date | Additional cassette batch number, if applicable | Additional cassette expiration date, if applicable | Hold-up volume of the UF/DF Skid | Total surface area of cassettes | Support Plate part number | Support Plate batch number | Support Plate expiration date | Logbook Number | CIPDS SAP Consumption Performed by/Date | D8: MEDIUM | E8: =IF(D8="LOW", 16, IF(D8="MEDIUM", 40, IF(D8="HIGH", 100, ""))) -> 40 | G8: 7.4 | H8: Record VF Product Information | I8: In the Step 7.6 “Virus Filtration Product Information” table:If a tank was used, N/A Vessels 2 and 3. For bag(s), N/A any unused Vessel fields.Record the net weight of each Virus Filtration Product from(MABR-0027575) MPR or the label of each product transport vessel.Record the tare weight of each Virus Filtration Product Vessel.Record the product concentration of each Virus Filtration Product Vessel.Record the corresponding DLIMS project number and sample number for the Virus Filtration Product(s) vessels. | J8: MEDIUM | K8: =IF(J8="LOW", 16, IF(J8="MEDIUM", 40, IF(J8="HIGH", 100, ""))) -> 40
A9: 7.3 | B9: Pre-Processing Verification | C9: Pre-Processing Activities for the UF/DF SkidVerify the data for the UF/DF Skid to be used.From the logbook, record in Step 7.4 the logbook number, the CIPDS batch number, and the date when the actions were documented.Ensure that the UF/DF Skid’s most immediate storage after sanitization has not exceeded 30 days storage.If the storage duration is greater than 30 days, contact a supervisor and document actions taken in Attachment 9: Comments Section. | D9: MEDIUM | E9: =IF(D9="LOW", 16, IF(D9="MEDIUM", 40, IF(D9="HIGH", 100, ""))) -> 40 | G9: 7.6 | H9: Calculate Total Grams VF Product per Vessel | I9: Calculate the total grams of Virus Filtration Product in each vessel.NOTE: N/A any unused Vessel fields below. | Virus Filtration (VF) Product Volume (Step 7.7) | Vessel 1 | L | Vessel 2, if applicable | L | Vessel 3, if applicable | L | Total grams of VF Product before sampling(Vessel 1 grams + Vessel 2 grams + Vessel 3 grams) | J9: MEDIUM | K9: =IF(J9="LOW", 16, IF(J9="MEDIUM", 40, IF(J9="HIGH", 100, ""))) -> 40
A10: 7.4 | B10: Record VF Product Information | C10: In the Step 7.6 “Virus Filtration Product Information” table:If a tank was used, N/A Vessels 2 and 3. For bag(s), N/A any unused Vessel fields.Record the net weight of each Virus Filtration Product from(MABR-0027575) MPR or the label of each product transport vessel.Record the tare weight of each Virus Filtration Product Vessel.Record the product concentration of each Virus Filtration Product Vessel.Record the corresponding DLIMS project number and sample number for the Virus Filtration Product(s) vessels. | D10: MEDIUM | E10: =IF(D10="LOW", 16, IF(D10="MEDIUM", 40, IF(D10="HIGH", 100, ""))) -> 40 | G10: 7.7 | H10: Calculate Minimum Membrane Surface Area | I10: Calculate the total membrane surface area needed for the UFDF process: | Total grams of VF Product before sampling(Step 7.8) | g | J10: MEDIUM | K10: =IF(J10="LOW", 16, IF(J10="MEDIUM", 40, IF(J10="HIGH", 100, ""))) -> 40
A11: 7.5 | B11: Calculate VF Product Volume per Vessel | C11: Calculate the Virus Filtration Product volume in each vessel.NOTE: N/A any unused Vessel fields below. | Virus Filtration Product Net Weight(Step 7.6) | Vessel 1 | kg | Vessel 2, if applicable | kg | Vessel 3, if applicable | kg | D11: MEDIUM | E11: =IF(D11="LOW", 16, IF(D11="MEDIUM", 40, IF(D11="HIGH", 100, ""))) -> 40 | G11: 8.12 | H11: Sample Retentate/Permeate — Record Results | I11: At the end of the recipe, take a sample of the retentate and permeate and record the results below. | Retentate Values | Conductivity (≤ 1 mS/cm) | Temperature (15 – 25°C) | Permeate Values | Conductivity (≤ 1 mS/cm) | Temperature (15 – 25°C) | J11: MEDIUM | K11: =IF(J11="LOW", 16, IF(J11="MEDIUM", 40, IF(J11="HIGH", 100, ""))) -> 40
A12: 7.6 | B12: Calculate Total Grams VF Product per Vessel | C12: Calculate the total grams of Virus Filtration Product in each vessel.NOTE: N/A any unused Vessel fields below. | Virus Filtration (VF) Product Volume (Step 7.7) | Vessel 1 | L | Vessel 2, if applicable | L | Vessel 3, if applicable | L | Total grams of VF Product before sampling(Vessel 1 grams + Vessel 2 grams + Vessel 3 grams) | D12: HIGH | E12: =IF(D12="LOW", 16, IF(D12="MEDIUM", 40, IF(D12="HIGH", 100, ""))) -> 100 | G12: 9.2 | H12: Mix VF Product (≥15 min) | I12: Mix the Virus Filtration product for at least 15 minutes and record mixing information below:Follow SOP-0080423 for the LevTech mixer. Follow SOP-0107095 for agitation in fixed tanks.If mixing by recirculation, N/A this step and document mixing in Attachment 7: Product Recirculation Work Sheet.N/A any unused Vessel fields below. | Vessel 1 | Mixer ID (if applicable) | Agitation Speed | Start Time | Duration (≥ 15 min) | Vessel 2, if applicable | Mixer ID (if applicable) | Agitation Speed | Start Time | Duration (≥ 15 min) | Vessel 3, if applicable | Mixer ID (if applicable) | Agitation Speed | Start Time | Duration (≥ 15 min) | J12: MEDIUM | K12: =IF(J12="LOW", 16, IF(J12="MEDIUM", 40, IF(J12="HIGH", 100, ""))) -> 40
A13: 7.7 | B13: Calculate Minimum Membrane Surface Area | C13: Calculate the total membrane surface area needed for the UFDF process: | Total grams of VF Product before sampling(Step 7.8) | g | D13: MEDIUM | E13: =IF(D13="LOW", 16, IF(D13="MEDIUM", 40, IF(D13="HIGH", 100, ""))) -> 40 | G13: 9.8 | H13: Weigh Product Vessels — Calculate Net Weight | I13: Weigh the product vessel(s) and record below. N/A any unused Vessel fields.Calculate the Net Weight for each vessel.The “Total Net Weight after sampling” is the sum of the net weights for each vessel. | Vessel | Gross Weight | Virus Filtration Product Vessel Tare Weight(Step 7.6) | Net Weight a | Total Net Weight of VF Product after sampling(Vessel 1 + Vessel 2 + Vessel 3) | Scale/Balance ID | Cal. Due Date | Net Weight = Gross weight – Virus Filtration Product Vessel Tare Weight | J13: MEDIUM | K13: =IF(J13="LOW", 16, IF(J13="MEDIUM", 40, IF(J13="HIGH", 100, ""))) -> 40
A14: 7.8 | B14: Verify Installed Surface Area ≥ Minimum | C14: Verify the total installed surface area of cassettes (Step 7.2) is greater than or equal to the minimum membrane surface area calculated in Step 7.9. | D14: LOW | E14: =IF(D14="LOW", 16, IF(D14="MEDIUM", 40, IF(D14="HIGH", 100, ""))) -> 16 | G14: 11.1 | H14: Obtain & Label Retentate Vessel (TK-1927) | I14: Obtain the Retentate Vessel.Label the vessel “Retentate Vessel”.Record the vessel’s tank ID, clean expiration date and time, sterilization expiration date and time, Cleaning and SIP Batch IDs and date of passed pressure test.Record the volume of the Retentate Vessel. | Tank ID | Cleaning Exp. Date / Time | Tank Date of Passed Pressure Test | Cleaning Batch ID | Sterilization Exp. Date/ Time | Sterilization Batch ID | Retentate Vessel Volume | Vent Filter Information | Part Number | Batch Number | Expiration Date | Serial Number | SAP Consumption Performed by/Date | J14: MEDIUM | K14: =IF(J14="LOW", 16, IF(J14="MEDIUM", 40, IF(J14="HIGH", 100, ""))) -> 40
A15: 8.1 | B15: WFI Setup and Charge | C15: Set up per SOP-0107111.WFI collected/obtained directly from the WFI Hold Tank (TK-1458) per SOP-0080303:Verify the SIP of the WFI Hold Tank was completed and the tank status is “Clean.”Before connecting to the UF skid, WFI Flush the TK-1458 WFI port on the transfer panel per the following instructions:Ensure an appropriately sized Tee with bleed valve is connected to the manual valve leading from TK-1458 on the transfer panel, then attach a clean hose to the other end of the Tee.Connect the other end of the hose to a process drain port.Ensure any valves on the process drain port are open, if applicable.Open the manual valve leading from the TK-1458 port. Ensure the valve is completely open.Flush TK-1458 through the transfer panel port manual valve to process drain for ≥30 seconds, then close the manual valve on the TK-1458 transfer panel port.N/A the bag information. WFI was/will be collected into a bag: Record the WFI collection vessel information.Verify that the WFI port has been flushed per SOP-0080185.Charge into the vessel and record the charge information. | Bag, if applicable | WFI Valve ID/Tank ID | WFI ChargeDate/Time | WFI Expiration Date/Time* | * The WFI Expiration Date/Time is 24 hours from the WFI Charge Date/Time. | SAP Consumption Performed by/Date | D15: MEDIUM | E15: =IF(D15="LOW", 16, IF(D15="MEDIUM", 40, IF(D15="HIGH", 100, ""))) -> 40 | G15: 11.6 | H15: Record Tare Weight Before Attachment | I15: Tare weight of Retentate Vessel before attachment | J15: MEDIUM | K15: =IF(J15="LOW", 16, IF(J15="MEDIUM", 40, IF(J15="HIGH", 100, ""))) -> 40
A16: 8.2 | B16: Confirm pH/Conductivity Meter Standardized | C16: Confirm that the pH meter has been standardized per SOP-0080297.Confirm that the conductivity meter has been standardized perSOP-0080297. | Meter ID | D16: MEDIUM | E16: =IF(D16="LOW", 16, IF(D16="MEDIUM", 40, IF(D16="HIGH", 100, ""))) -> 40 | G16: 14.11 | H16: Sample Retentate/Permeate (pH/Cond/Temp) | I16: Collect a sample from the permeate and retentate lines for pH, conductivity, and temperature measurement. Record the results below.NOTE: If the Retentate and Permeate pH values are not within range, contact a supervisor prior to proceeding and document actions taken in Attachment 9: Comments Section. | Retentate Values | pH (5.7 - 6.1) | Conductivity | Temperature (15 – 25°C) | Permeate Values | pH | Conductivity | Temperature (15 – 25°C) | J16: MEDIUM | K16: =IF(J16="LOW", 16, IF(J16="MEDIUM", 40, IF(J16="HIGH", 100, ""))) -> 40
A17: 8.3 | B17: Confirm Thermometer Calibration | C17: Confirm that the thermometer is within its calibration interval. Record the equipment ID of the thermometer used. | Thermometer ID | D17: LOW | E17: =IF(D17="LOW", 16, IF(D17="MEDIUM", 40, IF(D17="HIGH", 100, ""))) -> 16 | G17: 15.6 | H17: Record Conc 2 End Time/Weight/Volume | I17: Concentration 2 End Time | Retentate Weight * | Permeate Volume | J17: LOW | K17: =IF(J17="LOW", 16, IF(J17="MEDIUM", 40, IF(J17="HIGH", 100, ""))) -> 16
A18: 8.4 | B18: Ensure UF System Setup for WFI Flush | C18: Ensure that the Ultrafiltration (UF) system is set up for WFI flush of the installed cassettes according to SOP-0107111. | D18: MEDIUM | E18: =IF(D18="LOW", 16, IF(D18="MEDIUM", 40, IF(D18="HIGH", 100, ""))) -> 40 | G18: 16.34 | H18: Calculate Recovery Product Volume | I18: Calculate the volume of the Recovery Product after Transfer. | Net weight of Recovery Product after Transfer(Step 16.32) | kg | J18: MEDIUM | K18: =IF(J18="LOW", 16, IF(J18="MEDIUM", 40, IF(J18="HIGH", 100, ""))) -> 40
... A20: 8.6 | B20: Connect WFI to UF/DF Skid Feed Line | C20: Connect the WFI supply inlet to the UF/DF Skid feed line.Ensure that the retentate and permeate lines on the UF/DF Skid are directed to waste. | D20: MEDIUM | E20: =IF(D20="LOW", 16, IF(D20="MEDIUM", 40, IF(D20="HIGH", 100, ""))) -> 40 | G20: 18.4 | H20: Obtain SHC Filter | I20: Obtain an SHC filter per Section 4 and record the filter information below.NOTE: The bolded filter part number(s) in Section 4 require autoclaving. | Pre-Formulated Intermediate Product Filter Information | Part Number | Batch No. | Exp. Date | Autoclave Information, if applicable | AutoclaveCycle No. | SAP Consumption Performed by/Date | J20: MEDIUM | K20: =IF(J20="LOW", 16, IF(J20="MEDIUM", 40, IF(J20="HIGH", 100, ""))) -> 40
A21: 8.7 | B21: Calculate Target Flush Volume (22 L/m²) | C21: Calculate the target volume of solution needed for a 22.0 L/m2 WFI and Equilibration flushes. | Target Flush Volume | 22.0 L/m2 | D21: LOW | E21: =IF(D21="LOW", 16, IF(D21="MEDIUM", 40, IF(D21="HIGH", 100, ""))) -> 16 | G21: ATT-2 | H21: Operation Parameters | I21: Operation Parameters: 8-page recording form for Time, Pressures (Feed/Retentate/Permeate/ΔP), Pump Settings, Flow Rate, TMP, UV (OD), Weight, Totalizer, Temperature, Conductivity readings throughout UF/DF operations. | J21: HIGH | K21: =IF(J21="LOW", 16, IF(J21="MEDIUM", 40, IF(J21="HIGH", 100, ""))) -> 100
A22: 8.8 | B22: Run DF1244_Flush (Pre-Use WFI) | C22: Download and run DF1244_Flush according to SOP-0107111 to flush the UF/DF Skid with WFI.Record the batch ID and start time. The batch ID should follow this format:MPR Part Number_PrepWFI_Batch number_Processing DateNOTE: The membranes should be flushed no more than 24 hours before use. | Batch ID | Start Time | D22: MEDIUM | E22: =IF(D22="LOW", 16, IF(D22="MEDIUM", 40, IF(D22="HIGH", 100, ""))) -> 40 | G22: ATT-7 | H22: Product Recirculation Work Sheet | I22: Product Recirculation Work Sheet: Tubing details, pump ID, mixing start/end times, duration tracking for product recirculation. | J22: MEDIUM | K22: =IF(J22="LOW", 16, IF(J22="MEDIUM", 40, IF(J22="HIGH", 100, ""))) -> 40
A23: 8.9 | B23: Input Flush Volume Set Points | C23: At the user prompt, input the flush volume set points per the table below. | Process Step | Permeate Flush | Retentate Flush | D23: MEDIUM | E23: =IF(D23="LOW", 16, IF(D23="MEDIUM", 40, IF(D23="HIGH", 100, ""))) -> 40 | G23: ATT-8 | H23: Yield Calculations | I23: Yield Calculations: Pre-sampling mass, step yield, and MPR yield calculations. References PFI volume from Step 17.16 or 16.33. | J23: HIGH | K23: =IF(J23="LOW", 16, IF(J23="MEDIUM", 40, IF(J23="HIGH", 100, ""))) -> 100
A24: 8.1 | B24: Start Pre-Use WFI Flush Recipe | C24: Go to the Recipe Control screen on the UF/DF Skid HMI, and push START to initiate the pre-use WFI flush.Perform the WFI flush of the UF/DF Skid per SOP-0107111.Sample and document the flush conductivities per Step 8.12. | D24: MEDIUM | E24: =IF(D24="LOW", 16, IF(D24="MEDIUM", 40, IF(D24="HIGH", 100, ""))) -> 40 | G24: -- | H24: SOLO_AZ280 | I24: Attachment pulled from other batch records | J24: HIGH | K24: =IF(J24="LOW", 16, IF(J24="MEDIUM", 40, IF(J24="HIGH", 100, ""))) -> 100
A25: 8.11 | B25: Recipe Complete — Pump Stops | C25: At the completion of the recipe, the status changes from “Running” to “Complete” and the pump stops. | D25: MEDIUM | E25: =IF(D25="LOW", 16, IF(D25="MEDIUM", 40, IF(D25="HIGH", 100, ""))) -> 40 | G25: -- | H25: Recirculation Protocol | I25: Attachment pulled from other batch records | J25: MEDIUM | K25: =IF(J25="LOW", 16, IF(J25="MEDIUM", 40, IF(J25="HIGH", 100, ""))) -> 40
A26: 8.12 | B26: Sample Retentate/Permeate — Record Results | C26: At the end of the recipe, take a sample of the retentate and permeate and record the results below. | Retentate Values | Conductivity (≤ 1 mS/cm) | Temperature (15 – 25°C) | Permeate Values | Conductivity (≤ 1 mS/cm) | Temperature (15 – 25°C) | D26: MEDIUM | E26: =IF(D26="LOW", 16, IF(D26="MEDIUM", 40, IF(D26="HIGH", 100, ""))) -> 40 | G26: -- | H26: Casett Installation | I26: Attachment pulled from other batch records | J26: HIGH | K26: =IF(J26="LOW", 16, IF(J26="MEDIUM", 40, IF(J26="HIGH", 100, ""))) -> 100
A27: 8.13 | B27: Conductivity Check — Conditional N/A | C27: If the conductivity is in range, N/A the remainder of Section 8 and go to Section 9.If the conductivity is not in range, go to the next step. | D27: MEDIUM | E27: =IF(D27="LOW", 16, IF(D27="MEDIUM", 40, IF(D27="HIGH", 100, ""))) -> 40 | G27: -- | H27: VPro test work sheet | I27: Attachment pulled from other batch records | J27: LOW | K27: =IF(J27="LOW", 16, IF(J27="MEDIUM", 40, IF(J27="HIGH", 100, ""))) -> 16
A28: 8.14 | B28: Run DF1244_Flush (2nd WFI Flush) | C28: Download and run DF1244_Flush according to SOP-0107111 to flush the UF/DF Skid with WFI.Record the batch ID and start time. The batch ID should follow this format:MPR Part Number_PrepWFI2_Batch Number_Processing Date.NOTE: The membranes should be flushed no more than 24 hours prior to use. | Batch ID | Start Time | D28: MEDIUM | E28: =IF(D28="LOW", 16, IF(D28="MEDIUM", 40, IF(D28="HIGH", 100, ""))) -> 40 | G28: =COUNTA(Streamlined_Analysis_3[Step Num]) -> 21 | K28: =SUM(Streamlined_Analysis_3[Effort Hours (hrs)]) -> 1092
A29: 8.15 | B29: Input Flush Volume Set Points (2nd) | C29: At the user prompt, input the flush volumes per the table below. | Process Step | Permeate Flush | Retentate Flush | D29: MEDIUM | E29: =IF(D29="LOW", 16, IF(D29="MEDIUM", 40, IF(D29="HIGH", 100, ""))) -> 40
A30: 8.16 | B30: Start 2nd WFI Flush Recipe | C30: Go to the Recipe Control screen on the UF/DF Skid HMI, and push START to initiate the WFI flush of the UF/DF Skid.Perform the WFI flush of the UF/DF Skid per SOP-0107111.Sample and document the flush conductivities per Step 8.18. | D30: MEDIUM | E30: =IF(D30="LOW", 16, IF(D30="MEDIUM", 40, IF(D30="HIGH", 100, ""))) -> 40
A31: 8.17 | B31: Recipe Complete — Pump Stops | C31: At the completion of the recipe, the status changes from “Running” to “Complete” and the pump stops. | D31: MEDIUM | E31: =IF(D31="LOW", 16, IF(D31="MEDIUM", 40, IF(D31="HIGH", 100, ""))) -> 40
A32: 8.18 | B32: Sample Retentate/Permeate (2nd Flush) | C32: Take a sample of the retentate and permeate and record the results below.If the conductivities are not within the specified range after repeating the recipe, contact an area supervisor and document actions taken in Attachment 9: Comments Section. | Retentate Values | Conductivity (≤ 1 mS/cm) | Temperature (15 – 25°C) | Permeate Values | Conductivity (≤ 1 mS/cm) | Temperature (15 – 25°C) | D32: MEDIUM | E32: =IF(D32="LOW", 16, IF(D32="MEDIUM", 40, IF(D32="HIGH", 100, ""))) -> 40
A33: 9.1 | B33: Record Cold Storage Removal Time | C33: If the Virus Filtration Product was warmed up (from cold storage), ensure the time the product was removed from cold storage is recorded in Attachment 5: Hold Times. | D33: MEDIUM | E33: =IF(D33="LOW", 16, IF(D33="MEDIUM", 40, IF(D33="HIGH", 100, ""))) -> 40
A34: 9.2 | B34: Mix VF Product (≥15 min) | C34: Mix the Virus Filtration product for at least 15 minutes and record mixing information below:Follow SOP-0080423 for the LevTech mixer. Follow SOP-0107095 for agitation in fixed tanks.If mixing by recirculation, N/A this step and document mixing in Attachment 7: Product Recirculation Work Sheet.N/A any unused Vessel fields below. | Vessel 1 | Mixer ID (if applicable) | Agitation Speed | Start Time | Duration (≥ 15 min) | Vessel 2, if applicable | Mixer ID (if applicable) | Agitation Speed | Start Time | Duration (≥ 15 min) | Vessel 3, if applicable | Mixer ID (if applicable) | Agitation Speed | Start Time | Duration (≥ 15 min) | D34: MEDIUM | E34: =IF(D34="LOW", 16, IF(D34="MEDIUM", 40, IF(D34="HIGH", 100, ""))) -> 40
A35: 9.3 | B35: Collect Pre-Process Sample (-10) | C35: Remove at least the sample volume per Attachment 3: Sampling Record from each of the product collection vessel per SOP-0107097.If non-routine samples are requested by memo, complete Attachment 4: Non-Routine Sampling Record.N/A any unused Vessel fields below. | Sampling Date and Time, Vessel 1 | Sampling Date and Time, Vessel 2,if applicable | Sampling Date and Time, Vessel 3,if applicable | D35: MEDIUM | E35: =IF(D35="LOW", 16, IF(D35="MEDIUM", 40, IF(D35="HIGH", 100, ""))) -> 40
A36: 9.4 | B36: Aliquot Sample (-10) | C36: Aliquot the sample (sample designation: 8012475-10-1, 8012475-10-2, or 8012475-10-3, as applicable) per Attachment 3: Sampling Record.If applicable, aliquot non-routine samples per Attachment 4: Non-Routine Sampling Record.Label the sample per SOP-0107056. | D36: MEDIUM | E36: =IF(D36="LOW", 16, IF(D36="MEDIUM", 40, IF(D36="HIGH", 100, ""))) -> 40
A37: 9.5 | B37: Submit Sample to DLIMS | C37: Submit the sample to the storage location per SOP-0080295.Ensure the sampling time and location are updated in DLIMS. | D37: MEDIUM | E37: =IF(D37="LOW", 16, IF(D37="MEDIUM", 40, IF(D37="HIGH", 100, ""))) -> 40
A38: 9.6 | B38: Measure Sample Temperature | C38: Place the remaining sample in a 50 ml conical tube and measure the temperature of the sample per SOP-0107117.Record the reading below.N/A any unused Vessel fields below. | Vessel 1 Temperature | Vessel 2 Temperature, if applicable | Vessel 3 Temperature, if applicable | D38: MEDIUM | E38: =IF(D38="LOW", 16, IF(D38="MEDIUM", 40, IF(D38="HIGH", 100, ""))) -> 40
A39: 9.7 | B39: Conditional: Transfer Panel Setup | C39: If the VF product is in a bag or portable tank, N/A this step. Otherwise, continue below.In Purification, ensure the following:All the necessary transfer panel connections are made for transfer of the VF product to Formulation per SOP-0107099.The condensate flex hose on the transfer panel is removed and the manual valve that the flex hose was attached to is closed. UseSOP-0080548 for Large Purification fixed tanks and SOP-0080323 for Small Purification fixed tanks. | D39: MEDIUM | E39: =IF(D39="LOW", 16, IF(D39="MEDIUM", 40, IF(D39="HIGH", 100, ""))) -> 40
A40: 9.8 | B40: Weigh Product Vessels — Calculate Net Weight | C40: Weigh the product vessel(s) and record below. N/A any unused Vessel fields.Calculate the Net Weight for each vessel.The “Total Net Weight after sampling” is the sum of the net weights for each vessel. | Vessel | Gross Weight | Virus Filtration Product Vessel Tare Weight(Step 7.6) | Net Weight a | Total Net Weight of VF Product after sampling(Vessel 1 + Vessel 2 + Vessel 3) | Scale/Balance ID | Cal. Due Date | Net Weight = Gross weight – Virus Filtration Product Vessel Tare Weight | D40: MEDIUM | E40: =IF(D40="LOW", 16, IF(D40="MEDIUM", 40, IF(D40="HIGH", 100, ""))) -> 40
... A244: 21.2 | B244: Verify PFI Net Weight in SAP | C244: Verify that the PFI product net weight (from Step 18.8) is correctly inputted into SAP. | Review the Batch Production Record for completeness and submit for review. | D244: MEDIUM | E244: =IF(D244="LOW", 16, IF(D244="MEDIUM", 40, IF(D244="HIGH", 100, ""))) -> 40
A245: ATT-1 | B245: Tubing/Hose Information | C245: Tubing/Hose Information: Process tubing and hose tracking for Retentate Vessel connections. Serial numbers, cleaning expiration dates, autoclave cycle numbers. | D245: MEDIUM | E245: =IF(D245="LOW", 16, IF(D245="MEDIUM", 40, IF(D245="HIGH", 100, ""))) -> 40
...

Sheet Chromatography 1
A1: Chromatography 1 Batch Record Analysis
A2: Batch ID: PN - 8011840 | N2: Analysis Type | O2: Total Steps | P2: Effort Hours (hrs)
N3: Detailed Analysis | O3: =Detailed_Analysis_4[[#Totals],[Step Num]] -> 202 | P3: =Detailed_Analysis_4[[#Totals],[Effort Hours (hrs)]] -> 6508
N4: Streamlined Analysis | O4: =Streamlined_Analysis_4[[#Totals],[Step Num]] -> 29 | P4: =Streamlined_Analysis_4[[#Totals],[Effort Hours (hrs)]] -> 1520
A6: Step Num | B6: Title | C6: Brief Description | D6: Complexity | E6: Effort Hours (hrs) | G6: Step Num | H6: Title | I6: Brief Description | J6: Complexity | K6: Effort Hours (hrs)
A7: 5.1 | B7: Document Process Flowchart | C7: Process flowchart documenting the downstream process flow from Centrifuge Harvest (MABR-0026890 PN:8011847) through Affinity Chromatography to Virus Inactivation (MABR-0026892 PN:8011841). Includes buffer and solution flow paths. | D7: LOW | E7: =IF(D7="LOW", 16, IF(D7="MEDIUM", 40, IF(D7="HIGH", 100, ""))) -> 16 | G7: 5.1 | H7: Document Process Flowchart | I7: Process flowchart documenting the downstream process flow from Centrifuge Harvest (MABR-0026890 PN:8011847) through Affinity Chromatography to Virus Inactivation (MABR-0026892 PN:8011841). Includes buffer and solution flow paths. | J7: MEDIUM | K7: =IF(J7="LOW", 16, IF(J7="MEDIUM", 40, IF(J7="HIGH", 100, ""))) -> 40
A8: 5.2 | B8: Solution Batch Recording | C8: Record batch numbers and expiration dates for all chromatography solutions: Equilibration 1 (50 mM Tris pH 7.4, 8003734), Load (8011847 CM), Wash 1 (8011862), Wash 2 (A-005097), Elution (8002814), Acid Strip (A-005041), NaOH Strip (A0014-D), Column Sanitization, Column Storage (8002256), Skid Sanitization (1.0N NaOH A0191-D), Skid Storage (0.1N NaOH). Day 1 and Day 2 batch/expiry tracking for each. | D8: MEDIUM | E8: =IF(D8="LOW", 16, IF(D8="MEDIUM", 40, IF(D8="HIGH", 100, ""))) -> 40 | G8: 5.2 | H8: Solution Batch Recording | I8: Record batch numbers and expiration dates for all chromatography solutions: Equilibration 1 (50 mM Tris pH 7.4, 8003734), Load (8011847 CM), Wash 1 (8011862), Wash 2 (A-005097), Elution (8002814), Acid Strip (A-005041), NaOH Strip (A0014-D), Column Sanitization, Column Storage (8002256), Skid Sanitization (1.0N NaOH A0191-D), Skid Storage (0.1N NaOH). Day 1 and Day 2 batch/expiry tracking for each. | J8: MEDIUM | K8: =IF(J8="LOW", 16, IF(J8="MEDIUM", 40, IF(J8="HIGH", 100, ""))) -> 40
A9: 5.3 | B9: Additional Solution Batch Recording | C9: Blank form for recording replacement solution batch information if a solution needs to be changed during processing. Requires Part No., Batch No., Process Order No., and Expiry Date. Document changes in Attachment 10. | D9: LOW | E9: =IF(D9="LOW", 16, IF(D9="MEDIUM", 40, IF(D9="HIGH", 100, ""))) -> 16 | G9: 5.3 | H9: Additional Solution Batch Recording | I9: Blank form for recording replacement solution batch information if a solution needs to be changed during processing. Requires Part No., Batch No., Process Order No., and Expiry Date. Document changes in Attachment 10. | J9: MEDIUM | K9: =IF(J9="LOW", 16, IF(J9="MEDIUM", 40, IF(J9="HIGH", 100, ""))) -> 40
A10: 6.1 | B10: Process Notes and Operating Parameters | C10: 15 process notes defining operating conditions: all activities at 15-27°C, calculation assumptions (1L=1kg), flowrate ranges for steady state, skid flush flowrates at 477 L/hr (exception: Elution flush matches elution flowrate), temporary flowrate excursions acceptable, material expiry verification, equipment calibration verification, PAUSE function behavior, manual command supervisor signature requirements, recirculation mixing alternatives, alert limit documentation requirements, and over-pressurization flow rate adjustment procedures. | D10: LOW | E10: =IF(D10="LOW", 16, IF(D10="MEDIUM", 40, IF(D10="HIGH", 100, ""))) -> 16 | G10: 7.3 | H10: Harvest Tank Information Recording | I10: Record detailed harvest tank information: Tank ID, CIP Batch ID and Exp Date, SIP Batch ID and Exp Date, then tank parameters per SOP-0080524 including temperature setpoint (2-8°C or 15-25°C), pressure (0.0 psig), agitation speed. Record tare weight, mixer information, transfer panel port. Maximum CM hold time: 240 hours at 2-8°C including up to 120 hours at 15-25°C. Multi-table data recording with Day 1/Day 2 columns. | J10: HIGH | K10: =IF(J10="LOW", 16, IF(J10="MEDIUM", 40, IF(J10="HIGH", 100, ""))) -> 100
A11: 7.1 | B11: Harvest Process Direction | C11: Verify with supervisor whether harvesting into Downstream or Cell Culture. Conditional: if harvesting into Cell Culture, N/A Sections 7, 8, 9 and Attachments 1, 2, 3 and continue to Section 10. If Downstream, continue to Step 7.2. | D11: LOW | E11: =IF(D11="LOW", 16, IF(D11="MEDIUM", 40, IF(D11="HIGH", 100, ""))) -> 16 | G11: 11.1 | H11: Obtain and Verify Affinity Column | I11: Obtain Ecolabs (Purolite) Jetted A50 column and CPDS (FORM-0064069). Verify packed for AZD3427. Label column. Record: Media Name, Column ID, Packing Lot No., Column Diameter (80 cm), Bed Height (16-22 cm). Calculate Column Bed Volume (CV) = π/4 × D² × H. Record column pressures from CPDS: Column Inlet Pressure and Column Differential Pressure (ΔP). Multi-field data entry with calculations. | J11: HIGH | K11: =IF(J11="LOW", 16, IF(J11="MEDIUM", 40, IF(J11="HIGH", 100, ""))) -> 100
A12: 7.2 | B12: Harvest Tank Setup Verification | C12: Fill out harvest tank (Conditioned Medium collection tank) information in Step 7.3. | D12: LOW | E12: =IF(D12="LOW", 16, IF(D12="MEDIUM", 40, IF(D12="HIGH", 100, ""))) -> 16 | G12: 11.4 | H12: Verify Skid Sanitization and Storage Status | I12: Verify from the skid's logbook that the chromatography SKID was both: sanitized with 1.0 N Sodium Hydroxide (A0191-D) and stored in A0014-D: 0.1 N Sodium Hydroxide. Day 1 and Day 2 verification with dual signatures. | J12: MEDIUM | K12: =IF(J12="LOW", 16, IF(J12="MEDIUM", 40, IF(J12="HIGH", 100, ""))) -> 40
A13: 7.3 | B13: Harvest Tank Information Recording | C13: Record detailed harvest tank information: Tank ID, CIP Batch ID and Exp Date, SIP Batch ID and Exp Date, then tank parameters per SOP-0080524 including temperature setpoint (2-8°C or 15-25°C), pressure (0.0 psig), agitation speed. Record tare weight, mixer information, transfer panel port. Maximum CM hold time: 240 hours at 2-8°C including up to 120 hours at 15-25°C. Multi-table data recording with Day 1/Day 2 columns. | D13: HIGH | E13: =IF(D13="LOW", 16, IF(D13="MEDIUM", 40, IF(D13="HIGH", 100, ""))) -> 100 | G13: 13.4 | H13: Obtain and Install Product Filters | I13: Obtain product filters per Section 4. Record filter information (Part No., Batch No., Exp Date, Serial No.) for up to 3 filters. If tank: record CIP and SIP Batch IDs. Day 1 setup. | J13: HIGH | K13: =IF(J13="LOW", 16, IF(J13="MEDIUM", 40, IF(J13="HIGH", 100, ""))) -> 100
A14: 7.4 | B14: Obtain Sampler Components | C14: Record 5-Shot NovaSeptum Sampler cleaning cycle and expiry. Obtain and record: 1 Transfer Septum (4102085) or Transfer Unit (6002417), 1 Sampling Assembly 12x60mL (6002291), 3 NovaSeptum Bottle Applications 60mL (6002272). Multi-row material tracking table. | D14: MEDIUM | E14: =IF(D14="LOW", 16, IF(D14="MEDIUM", 40, IF(D14="HIGH", 100, ""))) -> 40 | G14: 15.7 | H14: Record Day 1 Total Filters Installed | I14: Record total number of filters installed for Day 1. | J14: LOW | K14: =IF(J14="LOW", 16, IF(J14="MEDIUM", 40, IF(J14="HIGH", 100, ""))) -> 16
A15: 7.5 | B15: Install Sampling on Harvest Tank | C15: Install the 5-Shot NovaSeptum sampler and bottle applications on the harvest tank per SOP-0107097. Signature required. | D15: LOW | E15: =IF(D15="LOW", 16, IF(D15="MEDIUM", 40, IF(D15="HIGH", 100, ""))) -> 16 | G15: 15.9 | H15: Record Day 1 Depth Filter Parameters | I15: Record surface area (m²), hold-up volume (L), and minimum WFI flush volume (L) for Day 1. | J15: HIGH | K15: =IF(J15="LOW", 16, IF(J15="MEDIUM", 40, IF(J15="HIGH", 100, ""))) -> 100
A16: 7.6 | B16: SAP Consumption Recording - Harvest Setup | C16: Record SAP consumption for materials used in Steps 7.3-7.5. | D16: LOW | E16: =IF(D16="LOW", 16, IF(D16="MEDIUM", 40, IF(D16="HIGH", 100, ""))) -> 16 | G16: 16.1 | H16: Verify Skid Meter Standardization | I16: Verify chromatography skid pH meter user standardized per SOP-0080402. Verify conductivity and UV meters within calibration. Record standardization date. Day 1 and Day 2. | J16: HIGH | K16: =IF(J16="LOW", 16, IF(J16="MEDIUM", 40, IF(J16="HIGH", 100, ""))) -> 100
A17: 7.7 | B17: pH/Conductivity Meter Verification | C17: Confirm pH and conductivity meter standardized per SOP-0080297. Record Meter ID. | D17: LOW | E17: =IF(D17="LOW", 16, IF(D17="MEDIUM", 40, IF(D17="HIGH", 100, ""))) -> 16 | G17: 16.2 | H17: Connect Buffers to Skid - Day 1 | I17: Connect 8 buffers to chromatography skid inlets: B4 (A0014-D NaOH Strip), B2 (A-005041 Acid Strip), A4 (8002814 Elution), B3 (A-005097 Wash 2), B1 (8011862 Wash 1), A3 (WFI), A1 (8003734 Equil 1/Load), A2 (8003734 Equil 2). Record Buffer Hold Tank IDs and Transfer Panel Valve IDs. | J17: MEDIUM | K17: =IF(J17="LOW", 16, IF(J17="MEDIUM", 40, IF(J17="HIGH", 100, ""))) -> 40
A18: 7.8 | B18: Connect Harvest Transfer Lines | C18: Connect hose to A12 on TP-1216, connect to appropriate transfer panel port on TP-1224 for harvest tank. Include tee and bleed valve for safe bleeding. | D18: MEDIUM | E18: =IF(D18="LOW", 16, IF(D18="MEDIUM", 40, IF(D18="HIGH", 100, ""))) -> 40 | G18: 16.3 | H18: Connect Buffers to Skid - Day 2 | I18: N/A if only 1 day. Repeat Day 1 buffer connections with Day 2 batch information. 8-inlet connection table. | J18: MEDIUM | K18: =IF(J18="LOW", 16, IF(J18="MEDIUM", 40, IF(J18="HIGH", 100, ""))) -> 40
... A30: 8.6 | B30: Set Harvest Tank Alarms | C30: Set and enable harvest tank alarms: High Agitation 25.0, Low Agitation 15.0, High Temperature per SOP, Low Temperature per SOP, High Pressure per SOP, Low Pressure per SOP. Record alarm setpoints table. | D30: MEDIUM | E30: =IF(D30="LOW", 16, IF(D30="MEDIUM", 40, IF(D30="HIGH", 100, ""))) -> 40 | G30: 20.3 | H30: Record Pre-Sampling Product Weight | I30: Record gross weight and calculate net weight of Filtered Affinity Product before sampling. Net Weight = Gross - Tare. | J30: LOW | K30: =IF(J30="LOW", 16, IF(J30="MEDIUM", 40, IF(J30="HIGH", 100, ""))) -> 16
A31: 8.7 | B31: Record CM Storage Parameters | C31: Record CM storage start time in Attachment 2. Select storage condition matching temperature setpoint. Maximum cumulative hold at 2-8°C is 240 hours including up to 120 hours at 15-25°C. | D31: LOW | E31: =IF(D31="LOW", 16, IF(D31="MEDIUM", 40, IF(D31="HIGH", 100, ""))) -> 16 | G31: ATT-1 | H31: Attachment 1: Conditioned Medium Sample Submission Chart | I31: Sample submission chart for CM (8011847-10) with 10+ samples: PROT_A_BIN (10mL), CHO_SYBR (10mL), EL_CHO_GEN (10mL), RED_RP_HPLC_FC_PEP (1mL), and retains. Each requires DLIMS Project Number, sample number, preload signature, tube type (PP3/PET), volume, test code. Labels per SOP-0107056. Includes nomenclature reference table. | J31: HIGH | K31: =IF(J31="LOW", 16, IF(J31="MEDIUM", 40, IF(J31="HIGH", 100, ""))) -> 100
A32: 8.8 | B32: Set/Verify Harvest Tank Parameters and Hold Time | C32: Set and/or verify harvest tank parameters per SOP-0080524. Maximum cumulative hold time of CM at 2-8°C is 240 hours including up to 120 hours at 15-25°C. Record CM storage start time in Attachment 2: Post-Harvest CM Hold Time Table. Select storage condition matching temperature setpoint. | D32: MEDIUM | E32: =IF(D32="LOW", 16, IF(D32="MEDIUM", 40, IF(D32="HIGH", 100, ""))) -> 40 | G32: ATT-2 | H32: Attachment 2: Post-Harvest CM Hold Time Table | I32: Multi-row hold time tracking table with columns: Hold #, Location (TK-xxxx), Temperature (RT or 2-8°C checkboxes), CM Storage Start time/date, CM Storage End time/date, Duration, Performed/Verified signatures. Up to 10 holds tracked. Calculate total storage duration at each temperature and combined total. Maximum hold: 240 hrs at 2-8°C including up to 120 hrs at 15-25°C. | J32: MEDIUM | K32: =IF(J32="LOW", 16, IF(J32="MEDIUM", 40, IF(J32="HIGH", 100, ""))) -> 40
A33: 8.9 | B33: Set and Enable Harvest Tank Alarms | C33: Set and enable harvest tank alarms per SOP-0080524: High Agitation (25.0), Low Agitation (15.0), High Temperature, Low Temperature, High Pressure, Low Pressure. Record setpoints in alarm table. | D33: MEDIUM | E33: =IF(D33="LOW", 16, IF(D33="MEDIUM", 40, IF(D33="HIGH", 100, ""))) -> 40 | G33: ATT-3 | H33: Attachment 3: Post-Storage CM Sampling Submission Chart | I33: Sample submission chart for post-storage CM (8011847-20). DLIMS test codes, volumes, tube types, storage temperatures. Dev Samples Green Form template. Includes preload signature and DLIMS project number tracking. | J33: MEDIUM | K33: =IF(J33="LOW", 16, IF(J33="MEDIUM", 40, IF(J33="HIGH", 100, ""))) -> 40
A34: 8.1 | B34: Record Harvest Tank Gross and Net Weight | C34: After tank pressure and weight have stabilized, obtain gross and net weight of harvest tank. Net Weight = Gross Weight - Tare Weight (Step 7.3). Record scale/balance ID. | D34: MEDIUM | E34: =IF(D34="LOW", 16, IF(D34="MEDIUM", 40, IF(D34="HIGH", 100, ""))) -> 40 | G34: ATT-4 | H34: Attachment 4: Sample Plan | I34: Comprehensive 2-page sample plan for Affinity Chromatography (8011840). Column effluent samples (-20 series) and product quality samples (-30 series). Lists DLIMS test names, volumes, locations, tube types, intermediate and DLIMS storage temperatures. Includes SOLO_A280 testing instructions. Development DLIMS Green Form template. STAT submissions in bold. | J34: MEDIUM | K34: =IF(J34="LOW", 16, IF(J34="MEDIUM", 40, IF(J34="HIGH", 100, ""))) -> 40
A35: 9.1 | B35: Agitate CM for Sampling | C35: Agitate CM for minimum 15 minutes prior to sampling. Record Mixer ID, Agitation Speed, Mix Start Time, Mix End Time. Do not turn off agitation after sampling. | D35: MEDIUM | E35: =IF(D35="LOW", 16, IF(D35="MEDIUM", 40, IF(D35="HIGH", 100, ""))) -> 40 | G35: ATT-8 | H35: Attachment 8: Adjusted Flowrate Table | I35: 3-page table for recording any adjusted flowrates during processing. Fields: Step Number, Cycle Number, Adjusted Flow Rate (L/hr), Reason for Change, Performed/Witnessed signatures. 10 rows per page, 3 pages = 30 possible entries. | J35: LOW | K35: =IF(J35="LOW", 16, IF(J35="MEDIUM", 40, IF(J35="HIGH", 100, ""))) -> 16
A36: 9.2 | B36: Collect CM Samples | C36: Collect samples per SOP-0107097. Record sampling date/time, gross weight, tare weight, net weight. Sample designation 8011847-10. | D36: MEDIUM | E36: =IF(D36="LOW", 16, IF(D36="MEDIUM", 40, IF(D36="HIGH", 100, ""))) -> 40 | G36: =COUNTA(Streamlined_Analysis_4[Step Num]) -> 29 | K36: =SUM(Streamlined_Analysis_4[Effort Hours (hrs)]) -> 1520
A37: 9.3 | B37: Label CM Samples | C37: Label each sample container per SOP-0107056 and Attachment 1: CM Sample Submission Chart (8011847-10). Attach DLIMS label. | D37: LOW | E37: =IF(D37="LOW", 16, IF(D37="MEDIUM", 40, IF(D37="HIGH", 100, ""))) -> 16
A38: 9.4 | B38: Verify DLIMS Submission | C38: Verify samples logged into DLIMS per SOP-0080295. Contact AS group for STAT HPLC Protein A Bindable sample (PROT_A_BIN). | D38: LOW | E38: =IF(D38="LOW", 16, IF(D38="MEDIUM", 40, IF(D38="HIGH", 100, ""))) -> 16
A39: 9.5 | B39: Submit Samples to AS | C39: Submit all samples (8011847-10) to AS per SOP-0080295. Enter sampling date/time in DLIMS. Ensure container types match DLIMS. | D39: LOW | E39: =IF(D39="LOW", 16, IF(D39="MEDIUM", 40, IF(D39="HIGH", 100, ""))) -> 16
A40: 9.6 | B40: Obtain Offline CM Measurements | C40: Obtain offline measurements of CM pH and Conductivity using calibrated meter. | D40: MEDIUM | E40: =IF(D40="LOW", 16, IF(D40="MEDIUM", 40, IF(D40="HIGH", 100, ""))) -> 40
A41: 9.7 | B41: Record CM Weight After Sampling | C41: Record gross weight and net weight of CM after sampling. Calculate net weight = gross - tare. | D41: LOW | E41: =IF(D41="LOW", 16, IF(D41="MEDIUM", 40, IF(D41="HIGH", 100, ""))) -> 16
A42: 9.8 | B42: Verify Hold Time Compliance | C42: Verify CM storage within allowed hold time. Record in Attachment 2. | D42: LOW | E42: =IF(D42="LOW", 16, IF(D42="MEDIUM", 40, IF(D42="HIGH", 100, ""))) -> 16
A43: 9.9 | B43: Record CM Weight After 8011847-10 Sampling | C43: Obtain gross and net weight of CM in harvest tank after 8011847-10 sampling. Record Gross Weight, calculate Net Weight = Gross Weight - Tare Weight (Step 7.3). Record Scale/Tank ID. | D43: MEDIUM | E43: =IF(D43="LOW", 16, IF(D43="MEDIUM", 40, IF(D43="HIGH", 100, ""))) -> 40
A44: 10.1 | B44: Record Room Number | C44: Record room where Affinity Chromatography will occur. Day 1 and Day 2. | D44: LOW | E44: =IF(D44="LOW", 16, IF(D44="MEDIUM", 40, IF(D44="HIGH", 100, ""))) -> 16
A45: 10.2 | B45: pH/Conductivity Meter Standardization | C45: Confirm pH and conductivity meter standardized per SOP-0080297. Record Meter ID for Day 1 and Day 2. | D45: LOW | E45: =IF(D45="LOW", 16, IF(D45="MEDIUM", 40, IF(D45="HIGH", 100, ""))) -> 16
A46: 10.3 | B46: Temperature Probe Verification | C46: Verify thermometer is within calibration interval per SOP-0107117. Record Thermometer ID for Day 1 and Day 2. | D46: LOW | E46: =IF(D46="LOW", 16, IF(D46="MEDIUM", 40, IF(D46="HIGH", 100, ""))) -> 16
A47: 10.4 | B47: Verify Equipment Calibration | C47: Verify balances and SoloVPE system within calibration per applicable SOPs. Record Equipment IDs for Day 1 and Day 2. | D47: LOW | E47: =IF(D47="LOW", 16, IF(D47="MEDIUM", 40, IF(D47="HIGH", 100, ""))) -> 16
A48: 10.5 | B48: Verify Data Logger and Process Trend | C48: Contact supervisor/designee and verify that the data logger is on. Verify the process trend for PK4000 is activated. Day 1 and Day 2. Then proceed: Day 1 processing continue to next step; Day 2 processing complete Steps 11.3 and 11.4 then continue to Step 12.17. | D48: MEDIUM | E48: =IF(D48="LOW", 16, IF(D48="MEDIUM", 40, IF(D48="HIGH", 100, ""))) -> 40
... A198: 22.3 | B198: Submit Batch Record for Review | C198: Review Batch Production Record for completeness and submit for review. Production initial/date. | D198: LOW | E198: =IF(D198="LOW", 16, IF(D198="MEDIUM", 40, IF(D198="HIGH", 100, ""))) -> 16
A199: ATT-1 | B199: Attachment 1: Conditioned Medium Sample Submission Chart | C199: Sample submission chart for CM (8011847-10) with 10+ samples: PROT_A_BIN (10mL), CHO_SYBR (10mL), EL_CHO_GEN (10mL), RED_RP_HPLC_FC_PEP (1mL), and retains. Each requires DLIMS Project Number, sample number, preload signature, tube type (PP3/PET), volume, test code. Labels per SOP-0107056. Includes nomenclature reference table. | D199: MEDIUM | E199: =IF(D199="LOW", 16, IF(D199="MEDIUM", 40, IF(D199="HIGH", 100, ""))) -> 40
A200: ATT-2 | B200: Attachment 2: Post-Harvest CM Hold Time Table | C200: Multi-row hold time tracking table with columns: Hold #, Location (TK-xxxx), Temperature (RT or 2-8°C checkboxes), CM Storage Start time/date, CM Storage End time/date, Duration, Performed/Verified signatures. Up to 10 holds tracked. Calculate total storage duration at each temperature and combined total. Maximum hold: 240 hrs at 2-8°C including up to 120 hrs at 15-25°C. | D200: HIGH | E200: =IF(D200="LOW", 16, IF(D200="MEDIUM", 40, IF(D200="HIGH", 100, ""))) -> 100
A201: ATT-3 | B201: Attachment 3: Post-Storage CM Sampling Submission Chart | C201: Sample submission chart for post-storage CM (8011847-20). DLIMS test codes, volumes, tube types, storage temperatures. Dev Samples Green Form template. Includes preload signature and DLIMS project number tracking. | D201: MEDIUM | E201: =IF(D201="LOW", 16, IF(D201="MEDIUM", 40, IF(D201="HIGH", 100, ""))) -> 40
...

Sheet Chromatography 2
A1: Chromatography 2 Batch Record Analysis
A2: Batch ID: PN - 8011762 | N2: Analysis Type | O2: Total Steps | P2: Effort Hours (hrs)
